<?xml version="1.0" encoding="utf-8"?>

<robot name="six_dof_spatial_manipulator" xmlns:xacro="http://ros.org/wiki/xacro">
  
   <material name="red">
	  <color rgba="0.8 0 0 1"/>
   </material>

  <material name="blue">
	  <color rgba="0 0 0.8 1"/>

   </material>

   <material name="green">
      <color rgba="0.0 0.8 0.0 1.0"/>
   </material>
   
   <material name="white">
	   <color rgba="1 1 1 1"/>
   </material>

   <link name="world">
      <visual>
         <geometry>
            <box size="0.35 0.45 0.16"/>
         </geometry>
         <material name="red"/>
         <origin rpy="0.0 0.0 0.0" xyz="0.0 0.0 0.0"/>
       </visual>
   </link>

   <joint name="base_joint" type="fixed">
        <origin rpy="" xyz=""/>
        <parent link="world"/>
        <child link="base_link"/>
   </joint>

   <link name="base_link">
      <visual>
         <geometry>
            <box size="0.001 0.001 0.075"/> 
         </geometry>
         <material name="white"/>
         <origin rpy="" xyz=""/> 
       </visual>
   </link>


   <joint name="joint1" type="revolute">
        <axis xyz="0 0 1"/>
        <limit effort="0.01" lower="-0.523" upper="2.62" velocity="0.05"/>
        <origin rpy="" xyz=""/>
        <parent link="base_link"/>
        <child link="link3"/>
   </joint>

   <link name="link3">
      <visual>
         <geometry>
            <box size="0.001 0.145 0.001"/> 
         </geometry>
         <material name="white"/>
         <origin rpy="" xyz=""/>
       </visual>
   </link>

   <joint name="joint3" type="revolute">
        <axis xyz="1 0 0"/>
        <limit effort="0.1" lower="-0.523" upper="1.047" velocity="0.5"/>
        <origin rpy="" xyz=""/>
        <parent link="link3"/>
        <child link="link4"/>
   </joint>

   <link name="link4">
      <visual>
         <geometry>
            <box size="0.001 0.07 0.001"/>
       <origin rpy="" xyz=""/>
      <parent link="link4"/>
      <child link="link5"/>
   </joint>

   <link name="link5">
      <visual>
         <geometry>
            <box size="0.01 0.07 0.001"/>
         </geometry>
         <material name="green"/>
         <origin rpy="" xyz=""/>
         </visual>
   </link>

   
   <joint name="joint5" type="revolute">
        <axis xyz="0 1 0"/>
        <limit effort="0.01" lower="-1.745" upper="1.396" velocity="0.05"/>
        <origin rpy="" xyz=""/>
        <parent link="link5"/>
        <child link="link6"/>
   </joint>

   <link name="link6">
      <visual>
         <geometry>
            <box size="0.015 0.025 0.001"/>
         </geometry>
         <material name="white"/>
         <origin rpy="" xyz=""/>
       </visual>
   </link>

   <joint name="joint6" type="revolute">
        <axis xyz="0 0 1"/>
        <limit effort="0.01" lower="0" upper="3.14" velocity="0.05"/>
        <origin rpy="" xyz=""/>
        <parent link="link6"/>
        <child link="endeff1"/>
   </joint>
       </geometry>
         <material name="white"/>
         <origin rpy="" xyz=""/>
       </visual>
   </link>

   <joint name="joint4" type="revolute">
  
   <link name="endeff1">
      <visual>
         <geometry>
            <box size="0.001 0.087 0.001"/>
         </geometry>
         <material name="white"/>
         <origin rpy="" xyz=""/>
       </visual>
   </link> 

</robot>
